Workbook

Sheet 人员
A1: 序号 | B1: 姓名 | C1: 性别 | D1: 出生日期 | E1: 联系电话 | F1: 身份证号 | G1: 常驻地点 | H1: 证书编号 | I1: 毕业学校 | J1: 专业 | K1: 入职时间 | L1: 工作年限 | N1: 职责 | O1: 最终学历 | P1: 毕业时间 | Q1: 从业年限 | R1: 持有的项目管理类证书软件设计师 | S1: 持有的项目管理类证书网络工程师 | T1: 持有的项目管理类证书信息系统项目管理师 | U1: 持有的项目管理类证书系统分析师 | V1: 持有的项目管理类证书系统集成项目管理工程师 | W1: 持有的项目管理类证书系统规划与管理师 | X1: 持有的项目管理类证书数据库系统工程师 | Y1: 持有的项目管理类证书信息系统监理师 | Z1: 持有的网络安全类证书CISP | AA1: 持有的网络安全类证书CISAW | AB1: 持有的网络安全类证书CCSC | AC1: 持有的网络安全类证书CISSP | AD1: 持有的网络安全类证书Security+ | AE1: 持有的网络安全类证书渗透测试 | AF1: 持有的网络安全类证书等保测评 | AG1: 持有的网络安全类证书数据安全治理 | AH1: 持有的软件开发技术类证书软件评测师 | AI1: 持有的软件开发技术类证书云计算 | AJ1: 持有的软件开发技术类证书大数据 | AK1: 持有的软件开发技术类证书开发语言 | AL1: 持有的软件开发技术类证书架构设计 | AM1: 其他证书 | AN1: 证书编号 | AO1: 证书有效期 | AP1: 是否为本单位缴纳社保在职人员
A2: 1 | B2: 王宁 | C2: 男 | D2: AAAAAABBBBBB | E2: 139xxxxxxx | F2: =VLOOKUP(B2,所有人!A:Q,16,FALSE) -> 130423198804104713 | G2: =VLOOKUP(B2,所有人!A:Q,9,FALSE) -> 济南市 | I2: =VLOOKUP(B2,所有人!A:O,12,FALSE) -> 中国地质大学 | J2: =VLOOKUP(B2,所有人!A:O,14,FALSE) -> 土木工程 | K2: =VLOOKUP(B2,所有人!A:Q,17,FALSE) -> 2020/01/13 | L2: =DATEDIF(K2,TODAY(),"Y") -> 6 | M2: =VLOOKUP(B2,所有人!A:Q,7,FALSE) -> 解决方案经理 | N2: 项目经理 | O2: 本科 | P2: 2008/10/08 | Q2: 17 | T2: 2018201370103169 | AA2: 2018CISAWOM1210(R2) | AC2: 733056 | AP2: 是 | AQ2: =COUNTA(T2:AN2) -> 5
A3: 2 | B3: 朱冰霞 | C3: 男 | D3: AAAAAABBBBBB | E3: 139xxxxxxx | F3: =VLOOKUP(B3,所有人!A:Q,16,FALSE) -> 440582199608155145 | G3: =VLOOKUP(B3,所有人!A:Q,9,FALSE) -> 广州市 | I3: =VLOOKUP(B3,所有人!A:O,12,FALSE) -> 广州大学华软软件学院 | J3: =VLOOKUP(B3,所有人!A:O,14,FALSE) -> 行政管理 | K3: =VLOOKUP(B3,所有人!A:Q,17,FALSE) -> 2021/04/21 | L3: =DATEDIF(K3,TODAY(),"Y") -> 5 | M3: =VLOOKUP(B3,所有人!A:Q,7,FALSE) -> 跨专业支持工程师 | N3: 项目经理 | O3: 本科 | P3: 2017/05/15 | Q3: 9 | T3: 31420201144010108636 | Z3: CNITSEC2021CISO24387 | AA3: 2024CISAWES0060 | AP3: 是 | AQ3: =COUNTA(T3:AN3) -> 4
A4: 3 | B4: 纪晓乐 | C4: 男 | D4: AAAAAABBBBBB | E4: 139xxxxxxx | F4: =VLOOKUP(B4,所有人!A:Q,16,FALSE) -> 372321198610058964 | G4: =VLOOKUP(B4,所有人!A:Q,9,FALSE) -> 天津市 | I4: =VLOOKUP(B4,所有人!A:O,12,FALSE) -> 天津职业技术师范大学 | J4: =VLOOKUP(B4,所有人!A:O,14,FALSE) -> 计算机科学与技术 | K4: =VLOOKUP(B4,所有人!A:Q,17,FALSE) -> 2017/06/01 | L4: =DATEDIF(K4,TODAY(),"Y") -> 9 | M4: =VLOOKUP(B4,所有人!A:Q,7,FALSE) -> 系统运营专家 | N4: 项目实施人员 | O4: 本科 | P4: 2011/07/01 | Q4: 14 | T4: 31420201112000100140 | Z4: CNITSEC2022CISO17999 | AP4: 是 | AQ4: =COUNTA(T4:AN4) -> 2
A5: 4 | B5: 崔宇 | C5: 男 | D5: AAAAAABBBBBB | E5: 139xxxxxxx | F5: =VLOOKUP(B5,所有人!A:Q,16,FALSE) -> 211224198309152415 | G5: =VLOOKUP(B5,所有人!A:Q,9,FALSE) -> 成都市 | I5: =VLOOKUP(B5,所有人!A:O,12,FALSE) -> 电子科技大学 | J5: =VLOOKUP(B5,所有人!A:O,14,FALSE) -> 通信工程 | K5: =VLOOKUP(B5,所有人!A:Q,17,FALSE) -> 2017/01/10 | L5: =DATEDIF(K5,TODAY(),"Y") -> 9 | M5: =VLOOKUP(B5,所有人!A:Q,7,FALSE) -> 实施运维工程师 | N5: 架构师 | O5: 本科 | P5: 2008/09/01 | Q5: 17 | T5: 31420190551010108532 | AA5: 2020CISAWSI3056 (R) | AP5: 是 | AQ5: =COUNTA(T5:AN5) -> 2
A6: 5 | B6: 李大健 | C6: 男 | D6: AAAAAABBBBBB | E6: 139xxxxxxx | F6: =VLOOKUP(B6,所有人!A:Q,16,FALSE) -> 22038119860619181X | G6: =VLOOKUP(B6,所有人!A:Q,9,FALSE) -> 杭州市 | I6: =VLOOKUP(B6,所有人!A:O,12,FALSE) -> 郑州轻工业学院 | J6: =VLOOKUP(B6,所有人!A:O,14,FALSE) -> 自动化 | K6: =VLOOKUP(B6,所有人!A:Q,17,FALSE) -> 2019/09/02 | L6: =DATEDIF(K6,TODAY(),"Y") -> 6 | M6: =VLOOKUP(B6,所有人!A:Q,7,FALSE) -> 系统运营经理 | N6: 质控工程师 | O6: 本科 | P6: 2010/07/01 | Q6: 15 | T6: 31420201133000103745 | AP6: 是 | AQ6: =COUNTA(T6:AN6) -> 1
A7: 6 | B7: 王鑫1 | C7: 男 | D7: AAAAAABBBBBB | E7: 139xxxxxxx | F7: =VLOOKUP(B7,所有人!A:Q,16,FALSE) -> 230107199209092473 | G7: =VLOOKUP(B7,所有人!A:Q,9,FALSE) -> 哈尔滨市 | I7: =VLOOKUP(B7,所有人!A:O,12,FALSE) -> 哈尔滨理工大学 | J7: =VLOOKUP(B7,所有人!A:O,14,FALSE) -> 计算机科学与技术 | K7: =VLOOKUP(B7,所有人!A:Q,17,FALSE) -> 2023/01/10 | L7: =DATEDIF(K7,TODAY(),"Y") -> 3 | M7: =VLOOKUP(B7,所有人!A:Q,7,FALSE) -> 解决方案经理 | N7: 项目经理 | O7: 本科 | P7: 2015/07/01 | Q7: 10 | T7: 31420201123010101611 | Z7: CNITSEC2017CISE01334 | AP7: 是 | AQ7: =COUNTA(T7:AN7) -> 2
A8: 7 | B8: 王泽君 | C8: 男 | D8: AAAAAABBBBBB | E8: 139xxxxxxx | F8: =VLOOKUP(B8,所有人!A:Q,16,FALSE) -> 42122119951201002X | G8: =VLOOKUP(B8,所有人!A:Q,9,FALSE) -> 海口市 | I8: =VLOOKUP(B8,所有人!A:O,12,FALSE) -> 上海海洋大学 | J8: =VLOOKUP(B8,所有人!A:O,14,FALSE) -> 物流工程 | K8: =VLOOKUP(B8,所有人!A:Q,17,FALSE) -> 2026/03/02 | L8: =DATEDIF(K8,TODAY(),"Y") -> 0 | M8: =VLOOKUP(B8,所有人!A:Q,7,FALSE) -> 系统运营经理 | N8: 项目经理 | O8: 本科 | P8: 2017/06/30 | Q8: 8 | T8: 31420211146010105177 | AP8: 是 | AQ8: =COUNTA(T8:AN8) -> 1
A9: 8 | B9: 范志华 | C9: 男 | D9: AAAAAABBBBBB | E9: 139xxxxxxx | F9: =VLOOKUP(B9,所有人!A:Q,16,FALSE) -> 412721198109041434 | G9: =VLOOKUP(B9,所有人!A:Q,9,FALSE) -> 济南市 | I9: =VLOOKUP(B9,所有人!A:O,12,FALSE) -> 江西财经理工学院 | J9: =VLOOKUP(B9,所有人!A:O,14,FALSE) -> 计算机 | K9: =VLOOKUP(B9,所有人!A:Q,17,FALSE) -> 2015/12/28 | L9: =DATEDIF(K9,TODAY(),"Y") -> 10 | M9: =VLOOKUP(B9,所有人!A:Q,7,FALSE) -> 系统运营经理 | N9: 项目经理 | O9: 大专及其以下 | P9: 2003/12/01 | Q9: 23 | T9: 31420191137010103072 | Z9: CNITSEC2022CISE05441 | AA9: 2020CISAWSI3056 (R) | AQ9: =COUNTA(T9:AN9) -> 3
A10: 9 | B10: 朱海楠 | C10: 男 | D10: AAAAAABBBBBB | E10: 139xxxxxxx | F10: =VLOOKUP(B10,所有人!A:Q,16,FALSE) -> 120222198804253824 | G10: =VLOOKUP(B10,所有人!A:Q,9,FALSE) -> 天津市 | I10: =VLOOKUP(B10,所有人!A:O,12,FALSE) -> 天津理工大学 | J10: =VLOOKUP(B10,所有人!A:O,14,FALSE) -> 信息与计算科学 | K10: =VLOOKUP(B10,所有人!A:Q,17,FALSE) -> 2023/10/09 | L10: =DATEDIF(K10,TODAY(),"Y") -> 2 | M10: =VLOOKUP(B10,所有人!A:Q,7,FALSE) -> 系统运营经理 | N10: 项目实施人员 | O10: 本科 | P10: 2011/10/10 | Q10: 15 | T10: 17201120097 | AQ10: =COUNTA(T10:AN10) -> 1
A11: 10 | B11: 赵卫斌1 | C11: 男 | D11: AAAAAABBBBBB | E11: 139xxxxxxx | F11: =VLOOKUP(B11,所有人!A:Q,16,FALSE) -> 410826198105183537 | G11: =VLOOKUP(B11,所有人!A:Q,9,FALSE) -> 郑州市 | I11: =VLOOKUP(B11,所有人!A:O,12,FALSE) -> 北京外国语大学 | J11: =VLOOKUP(B11,所有人!A:O,14,FALSE) -> 英语 | K11: =VLOOKUP(B11,所有人!A:Q,17,FALSE) -> 2023/12/04 | L11: =DATEDIF(K11,TODAY(),"Y") -> 2 | M11: =VLOOKUP(B11,所有人!A:Q,7,FALSE) -> 实施运维工程师 | N11: 质控工程师 | O11: 本科 | P11: 2002/05/08 | Q11: 24 | T11: 31420191141010103684 | AQ11: =COUNTA(T11:AN11) -> 1
A12: 11 | B12: 陈宇 | C12: 男 | D12: AAAAAABBBBBB | E12: 139xxxxxxx | F12: =VLOOKUP(B12,所有人!A:Q,16,FALSE) -> 150103197505051030 | G12: =VLOOKUP(B12,所有人!A:Q,9,FALSE) -> 呼和浩特市 | I12: =VLOOKUP(B12,所有人!A:O,12,FALSE) -> 内蒙古大学 | J12: =VLOOKUP(B12,所有人!A:O,14,FALSE) -> 工商管理 | K12: =VLOOKUP(B12,所有人!A:Q,17,FALSE) -> 2020/09/14 | L12: =DATEDIF(K12,TODAY(),"Y") -> 5 | M12: =VLOOKUP(B12,所有人!A:Q,7,FALSE) -> 解决方案经理 | N12: 项目经理 | O12: 硕士研究生 | P12: 1998/09/01 | Q12: 27 | T12: 13101150015 | Z12: CNITSEC2023CISP-DSG18521 | AM12: PMP | AN12: 49810 | AP12: 是 | AQ12: =COUNTA(T12:AN12) -> 5
A13: 12 | B13: 崔渊博 | C13: 男 | D13: AAAAAABBBBBB | E13: 139xxxxxxx | F13: =VLOOKUP(B13,所有人!A:Q,16,FALSE) -> 413028198110273010 | G13: =VLOOKUP(B13,所有人!A:Q,9,FALSE) -> 北京市 | I13: =VLOOKUP(B13,所有人!A:O,12,FALSE) -> 东北大学 | J13: =VLOOKUP(B13,所有人!A:O,14,FALSE) -> 计算机系统结构 | K13: =VLOOKUP(B13,所有人!A:Q,17,FALSE) -> 2015/06/10 | L13: =DATEDIF(K13,TODAY(),"Y") -> 11 | M13: =VLOOKUP(B13,所有人!A:Q,7,FALSE) -> 部门总监 | N13: 架构师 | O13: 硕士研究生 | P13: 2006/02/14 | Q13: 20 | T13: 16101110794 | Z13: CNITSEC2019CISE04325 | AA13: 2023CISAWSS0420 | AP13: 是 | AQ13: =COUNTA(T13:AN13) -> 3
A14: 13 | B14: 李跃波 | C14: 男 | D14: AAAAAABBBBBB | E14: 139xxxxxxx | F14: =VLOOKUP(B14,所有人!A:Q,16,FALSE) -> 13042919820412003X | G14: =VLOOKUP(B14,所有人!A:Q,9,FALSE) -> 太原市 | I14: =VLOOKUP(B14,所有人!A:O,12,FALSE) -> 郑州大学 | J14: =VLOOKUP(B14,所有人!A:O,14,FALSE) -> 计算机科学与技术 | K14: =VLOOKUP(B14,所有人!A:Q,17,FALSE) -> 2021/03/30 | L14: =DATEDIF(K14,TODAY(),"Y") -> 5 | M14: =VLOOKUP(B14,所有人!A:Q,7,FALSE) -> 项目经理 | N14: 项目实施人员 | O14: 本科 | P14: 2005/08/01 | Q14: 20 | T14: 15006923 | AA14: 2023CSAWSI0952 | AM14: PMP | AN14: 2966782 | AP14: 是 | AQ14: =COUNTA(T14:AN14) -> 5
A15: 14 | B15: 胡兵 | C15: 男 | D15: AAAAAABBBBBB | E15: 139xxxxxxx | F15: =VLOOKUP(B15,所有人!A:Q,16,FALSE) -> 440232198508120012 | G15: =VLOOKUP(B15,所有人!A:Q,9,FALSE) -> 北京市 | I15: =VLOOKUP(B15,所有人!A:O,12,FALSE) -> 北京理工大学 | J15: =VLOOKUP(B15,所有人!A:O,14,FALSE) -> 网络工程 | K15: =VLOOKUP(B15,所有人!A:Q,17,FALSE) -> 2011/06/16 | L15: =DATEDIF(K15,TODAY(),"Y") -> 15 | M15: =VLOOKUP(B15,所有人!A:Q,7,FALSE) -> 副总裁兼事业部副总经理 | N15: 项目实施人员 | O15: 本科 | P15: 2008/03/01 | Q15: 18 | Z15: CNITSEC2014CISE01881 | AP15: 是 | AQ15: =COUNTA(T15:AN15) -> 3
A16: 15 | B16: 吴涛 | C16: 男 | D16: AAAAAABBBBBB | E16: 139xxxxxxx | F16: =VLOOKUP(B16,所有人!A:Q,16,FALSE) -> 110105198112152113 | G16: =VLOOKUP(B16,所有人!A:Q,9,FALSE) -> 北京市 | I16: =VLOOKUP(B16,所有人!A:O,12,FALSE) -> 北京国际商务学院 | J16: =VLOOKUP(B16,所有人!A:O,14,FALSE) -> 计算机网络管理 | K16: =VLOOKUP(B16,所有人!A:Q,17,FALSE) -> 2011/04/15 | L16: =DATEDIF(K16,TODAY(),"Y") -> 15 | M16: =VLOOKUP(B16,所有人!A:Q,7,FALSE) -> 中心副总经理 | N16: 项目实施人员 | O16: 本科 | P16: 2000/07/01 | Q16: 25 | Z16: CNITSEC2019CISE08096 | AA16: 2020CISAWSI2995(R) | AP16: 是 | AQ16: =COUNTA(T16:AN16) -> 3
A17: 16 | B17: 林阳 | C17: 男 | D17: AAAAAABBBBBB | E17: 139xxxxxxx | F17: =VLOOKUP(B17,所有人!A:Q,16,FALSE) -> 360301199402180012 | G17: =VLOOKUP(B17,所有人!A:Q,9,FALSE) -> 北京市 | I17: =VLOOKUP(B17,所有人!A:O,12,FALSE) -> 华中科技大学文华学院 | J17: =VLOOKUP(B17,所有人!A:O,14,FALSE) -> 通信工程 | K17: =VLOOKUP(B17,所有人!A:Q,17,FALSE) -> 2016/06/23 | L17: =DATEDIF(K17,TODAY(),"Y") -> 10 | M17: =VLOOKUP(B17,所有人!A:Q,7,FALSE) -> 项目经理 | N17: 项目经理 | O17: 本科 | P17: 2016/06/23 | Q17: 9 | Z17: CNITSEC2021CISE22549 | AA17: 2023CISAWSI0944 | AM17: PMP | AN17: 2945160 | AP17: 是 | AQ17: =COUNTA(T17:AN17) -> 4
A18: 17 | B18: 史祥鹏 | C18: 男 | D18: AAAAAABBBBBB | E18: 139xxxxxxx | F18: =VLOOKUP(B18,所有人!A:Q,16,FALSE) -> 622425198210131213 | G18: =VLOOKUP(B18,所有人!A:Q,9,FALSE) -> 兰州市 | I18: =VLOOKUP(B18,所有人!A:O,12,FALSE) -> 中国管理软件学院 | J18: =VLOOKUP(B18,所有人!A:O,14,FALSE) -> 计算机软件及应用 | K18: =VLOOKUP(B18,所有人!A:Q,17,FALSE) -> 2010/11/01 | L18: =DATEDIF(K18,TODAY(),"Y") -> 15 | M18: =VLOOKUP(B18,所有人!A:Q,7,FALSE) -> 部门总监 | N18: 项目实施人员 | O18: 本科 | P18: 2006/01/01 | Q18: 20 | AA18: 2020CSAWOM2667(R) | AP18: 是 | AQ18: =COUNTA(T18:AN18) -> 3
A19: 18 | B19: 张利强 | C19: 男 | D19: AAAAAABBBBBB | E19: 139xxxxxxx | F19: =VLOOKUP(B19,所有人!A:Q,16,FALSE) -> 650103197809202318 | G19: =VLOOKUP(B19,所有人!A:Q,9,FALSE) -> 乌鲁木齐市 | I19: =VLOOKUP(B19,所有人!A:O,12,FALSE) -> 大连理工大学 | J19: =VLOOKUP(B19,所有人!A:O,14,FALSE) -> 电子与通信工程 | K19: =VLOOKUP(B19,所有人!A:Q,17,FALSE) -> 2020/09/01 | L19: =DATEDIF(K19,TODAY(),"Y") -> 5 | M19: =VLOOKUP(B19,所有人!A:Q,7,FALSE) -> 区域首席客户经理 | N19: 测试人员 | O19: 本科 | P19: 2001/07/01 | Q19: 24 | AA19: 2023CISAWSI0958 | AM19: PMP | AN19: 509061 | AP19: 是 | AQ19: =COUNTA(T19:AN19) -> 4
A20: 19 | B20: 刘晟鑫 | C20: 男 | D20: AAAAAABBBBBB | E20: 139xxxxxxx | F20: =VLOOKUP(B20,所有人!A:Q,16,FALSE) -> 340503198705090415 | G20: =VLOOKUP(B20,所有人!A:Q,9,FALSE) -> 广州市 | I20: =VLOOKUP(B20,所有人!A:O,12,FALSE) -> 中国人民大学 | J20: =VLOOKUP(B20,所有人!A:O,14,FALSE) -> 工商管理 | K20: =VLOOKUP(B20,所有人!A:Q,17,FALSE) -> 2011/09/01 | L20: =DATEDIF(K20,TODAY(),"Y") -> 14 | M20: =VLOOKUP(B20,所有人!A:Q,7,FALSE) -> 部门总监 | N20: 需求分析专家 | O20: 本科 | P20: 2009/07/01 | Q20: 16 | Z20: CNITSEC2019CISE04352 | AA20: 2020CISAWSI2955(R) | AP20: 是 | AQ20: =COUNTA(T20:AN20) -> 3
A21: 20 | B21: 王龙 | C21: 男 | D21: AAAAAABBBBBB | E21: 139xxxxxxx | F21: =VLOOKUP(B21,所有人!A:Q,16,FALSE) -> 230227199207170811 | G21: =VLOOKUP(B21,所有人!A:Q,9,FALSE) -> 北京市 | I21: =VLOOKUP(B21,所有人!A:O,12,FALSE) -> 佳木斯大学 | J21: =VLOOKUP(B21,所有人!A:O,14,FALSE) -> 通信工程 | K21: =VLOOKUP(B21,所有人!A:Q,17,FALSE) -> 2014/07/01 | L21: =DATEDIF(K21,TODAY(),"Y") -> 11 | M21: =VLOOKUP(B21,所有人!A:Q,7,FALSE) -> Java工程师 | N21: 质控工程师 | O21: 本科 | P21: 2014/07/01 | Q21: 11 | AM21: PMP | AN21: 2619774 | AP21: 是 | AQ21: =COUNTA(T21:AN21) -> 4
A22: 21 | B22: 董清辉 | C22: 男 | D22: AAAAAABBBBBB | E22: 139xxxxxxx | F22: =VLOOKUP(B22,所有人!A:Q,16,FALSE) -> 130731198604130630 | G22: =VLOOKUP(B22,所有人!A:Q,9,FALSE) -> 北京市 | I22: =VLOOKUP(B22,所有人!A:O,12,FALSE) -> 北京邮电大学 | J22: =VLOOKUP(B22,所有人!A:O,14,FALSE) -> 计算机科学与技术 | K22: =VLOOKUP(B22,所有人!A:Q,17,FALSE) -> 2015/12/28 | L22: =DATEDIF(K22,TODAY(),"Y") -> 10 | M22: =VLOOKUP(B22,所有人!A:Q,7,FALSE) -> 系统可靠性监测专家 | N22: 项目实施人员 | O22: 本科 | P22: 2008/07/01 | Q22: 17 | Z22: CNITSEC2019CISE04353 | AA22: 2017CISAWES0219 (R3) | AP22: 是 | AQ22: =COUNTA(T22:AN22) -> 3
A23: 22 | B23: 袁林 | C23: 男 | D23: AAAAAABBBBBB | E23: 139xxxxxxx | F23: =VLOOKUP(B23,所有人!A:Q,16,FALSE) -> 210204197611055332 | G23: =VLOOKUP(B23,所有人!A:Q,9,FALSE) -> 大连市 | I23: =VLOOKUP(B23,所有人!A:O,12,FALSE) -> 辽宁师范大学 | J23: =VLOOKUP(B23,所有人!A:O,14,FALSE) -> 应用电子技术 | K23: =VLOOKUP(B23,所有人!A:Q,17,FALSE) -> 2017/09/01 | L23: =DATEDIF(K23,TODAY(),"Y") -> 8 | M23: =VLOOKUP(B23,所有人!A:Q,7,FALSE) -> 中心副总经理 | N23: 测试人员 | O23: 本科 | P23: 1999/07/22 | Q23: 26 | Z23: CNITSEC2019CISE04334 | AP23: 是 | AQ23: =COUNTA(T23:AN23) -> 3
A24: 23 | B24: 刘武旭 | C24: 男 | D24: AAAAAABBBBBB | E24: 139xxxxxxx | F24: =VLOOKUP(B24,所有人!A:Q,16,FALSE) -> 412725198512126978 | G24: =VLOOKUP(B24,所有人!A:Q,9,FALSE) -> 郑州市 | I24: =VLOOKUP(B24,所有人!A:O,12,FALSE) -> 河南工业大学 | J24: =VLOOKUP(B24,所有人!A:O,14,FALSE) -> 计算机科学与技术 | K24: =VLOOKUP(B24,所有人!A:Q,17,FALSE) -> 2015/08/21 | L24: =DATEDIF(K24,TODAY(),"Y") -> 10 | M24: =VLOOKUP(B24,所有人!A:Q,7,FALSE) -> 客户总监 | N24: 项目经理 | O24: 本科 | P24: 2008/08/01 | Q24: 17 | Z24: CNITSEC2019CISE04376 | AA24: 2023CISAWSS0384 | AM24: PMP | AN24: 3082489 | AP24: 是 | AQ24: =COUNTA(T24:AN24) -> 4
A25: 24 | B25: 邸学锋 | C25: 男 | D25: AAAAAABBBBBB | E25: 139xxxxxxx | F25: =VLOOKUP(B25,所有人!A:Q,16,FALSE) -> 510108197603101539 | G25: =VLOOKUP(B25,所有人!A:Q,9,FALSE) -> 大连市 | I25: =VLOOKUP(B25,所有人!A:O,12,FALSE) -> 电子科技大学 | J25: =VLOOKUP(B25,所有人!A:O,14,FALSE) -> 计算机通信 | K25: =VLOOKUP(B25,所有人!A:Q,17,FALSE) -> 2017/08/10 | L25: =DATEDIF(K25,TODAY(),"Y") -> 8 | M25: =VLOOKUP(B25,所有人!A:Q,7,FALSE) -> C语言工程师 | N25: 质控工程师 | O25: 本科 | P25: 1999/07/01 | Q25: 26 | Z25: CNITSEC2019CISE04335 | AP25: 是 | AQ25: =COUNTA(T25:AN25) -> 3
A26: 25 | B26: 姚瑞 | C26: 男 | D26: AAAAAABBBBBB | E26: 139xxxxxxx | F26: =VLOOKUP(B26,所有人!A:Q,16,FALSE) -> 130726199005084517 | G26: =VLOOKUP(B26,所有人!A:Q,9,FALSE) -> 北京市 | I26: =VLOOKUP(B26,所有人!A:O,12,FALSE) -> 哈尔滨华德学院 | J26: =VLOOKUP(B26,所有人!A:O,14,FALSE) -> 自动化 | K26: =VLOOKUP(B26,所有人!A:Q,17,FALSE) -> 2018/04/08 | L26: =DATEDIF(K26,TODAY(),"Y") -> 8 | M26: =VLOOKUP(B26,所有人!A:Q,7,FALSE) -> Java工程师 | N26: 项目实施人员 | O26: 本科 | P26: 2014/08/08 | Q26: 11 | AM26: PMP | AN26: 2628281 | AP26: 是 | AQ26: =COUNTA(T26:AN26) -> 4
A27: 26 | B27: 贾立军 | C27: 男 | D27: AAAAAABBBBBB | E27: 139xxxxxxx | F27: =VLOOKUP(B27,所有人!A:Q,16,FALSE) -> 21132419820307301X | G27: =VLOOKUP(B27,所有人!A:Q,9,FALSE) -> 大连市 | I27: =VLOOKUP(B27,所有人!A:O,12,FALSE) -> 中央广播电视大学 | J27: =VLOOKUP(B27,所有人!A:O,14,FALSE) -> 计算机科学与技术 | K27: =VLOOKUP(B27,所有人!A:Q,17,FALSE) -> 2017/09/01 | L27: =DATEDIF(K27,TODAY(),"Y") -> 8 | M27: =VLOOKUP(B27,所有人!A:Q,7,FALSE) -> 组长 | N27: 测试人员 | O27: 本科 | P27: 2004/07/08 | Q27: 21 | Z27: CNITSEC2019CISE04337 | AP27: 是 | AQ27: =COUNTA(T27:AN27) -> 3
A28: 27 | B28: 刘道林 | C28: 男 | D28: AAAAAABBBBBB | E28: 139xxxxxxx | F28: =VLOOKUP(B28,所有人!A:Q,16,FALSE) -> 210204198206286772 | G28: =VLOOKUP(B28,所有人!A:Q,9,FALSE) -> 大连市 | I28: =VLOOKUP(B28,所有人!A:O,12,FALSE) -> 大连工业大学 | J28: =VLOOKUP(B28,所有人!A:O,14,FALSE) -> 机械设计及理论 | K28: =VLOOKUP(B28,所有人!A:Q,17,FALSE) -> 2019/06/03 | L28: =DATEDIF(K28,TODAY(),"Y") -> 7 | M28: =VLOOKUP(B28,所有人!A:Q,7,FALSE) -> 部门副总监 | N28: 项目经理 | O28: 硕士研究生 | P28: 2008/04/21 | Q28: 18 | Z28: CNITSEC2019CISE04340 | AP28: 是 | AQ28: =COUNTA(T28:AN28) -> 3
A29: 28 | B29: 苏万龙 | C29: 男 | D29: AAAAAABBBBBB | E29: 139xxxxxxx | F29: =VLOOKUP(B29,所有人!A:Q,16,FALSE) -> 230182198701244219 | G29: =VLOOKUP(B29,所有人!A:Q,9,FALSE) -> 广州市 | I29: =VLOOKUP(B29,所有人!A:O,12,FALSE) -> 广西工学院鹿山学院 | J29: =VLOOKUP(B29,所有人!A:O,14,FALSE) -> 电子信息工程 | K29: =VLOOKUP(B29,所有人!A:Q,17,FALSE) -> 2021/06/15 | L29: =DATEDIF(K29,TODAY(),"Y") -> 5 | M29: =VLOOKUP(B29,所有人!A:Q,7,FALSE) -> 项目经理 | N29: 架构师 | O29: 本科 | P29: 2011/01/24 | Q29: 15 | Z29: CNTSECICSO18 | AA29: 2024CISAWES0004 | AP29: 是 | AQ29: =COUNTA(T29:AN29) -> 3
A30: 29 | B30: 张俊 | C30: 男 | D30: AAAAAABBBBBB | E30: 139xxxxxxx | F30: =VLOOKUP(B30,所有人!A:Q,16,FALSE) -> 320482198808301816 | G30: =VLOOKUP(B30,所有人!A:Q,9,FALSE) -> 南京市 | I30: =VLOOKUP(B30,所有人!A:O,12,FALSE) -> 南京大学 | J30: =VLOOKUP(B30,所有人!A:O,14,FALSE) -> 软件工程 | K30: =VLOOKUP(B30,所有人!A:Q,17,FALSE) -> 2010/07/26 | L30: =DATEDIF(K30,TODAY(),"Y") -> 15 | M30: =VLOOKUP(B30,所有人!A:Q,7,FALSE) -> 项目经理 | N30: 需求分析专家 | O30: 本科 | P30: 2010/07/07 | Q30: 15 | Z30: CNITSEC2019CISE04359 | AA30: 2020CISAWSI2947 (R) | AM30: PMP | AN30: 1634623 | AP30: 是 | AQ30: =COUNTA(T30:AN30) -> 4
A31: 30 | B31: 范磊波 | C31: 男 | D31: AAAAAABBBBBB | E31: 139xxxxxxx | F31: =VLOOKUP(B31,所有人!A:Q,16,FALSE) -> 430124199007167119 | G31: =VLOOKUP(B31,所有人!A:Q,9,FALSE) -> 武汉市 | I31: =VLOOKUP(B31,所有人!A:O,12,FALSE) -> 湖南城市学院 | J31: =VLOOKUP(B31,所有人!A:O,14,FALSE) -> 信息与技术科学 | K31: =VLOOKUP(B31,所有人!A:Q,17,FALSE) -> 2017/04/05 | L31: =DATEDIF(K31,TODAY(),"Y") -> 9 | M31: =VLOOKUP(B31,所有人!A:Q,7,FALSE) -> 组长 | N31: 测试人员 | O31: 本科 | P31: 2013/11/17 | Q31: 12 | Z31: CNTTSEC2023CISO12148 | AA31: 2018CISAWSS0446 (R2) | AM31: PMP | AN31: 3481341 | AP31: 是 | AQ31: =COUNTA(T31:AN31) -> 4
A32: 31 | B32: 季斌 | C32: 男 | D32: AAAAAABBBBBB | E32: 139xxxxxxx | F32: =VLOOKUP(B32,所有人!A:Q,16,FALSE) -> 370121197511037714 | G32: =VLOOKUP(B32,所有人!A:Q,9,FALSE) -> 济南市 | I32: =VLOOKUP(B32,所有人!A:O,12,FALSE) -> 北京外国语大学 | J32: =VLOOKUP(B32,所有人!A:O,14,FALSE) -> 英语 | K32: =VLOOKUP(B32,所有人!A:Q,17,FALSE) -> 2021/05/14 | L32: =DATEDIF(K32,TODAY(),"Y") -> 5 | M32: =VLOOKUP(B32,所有人!A:Q,7,FALSE) -> 区域首席客户经理 | N32: 项目实施人员 | O32: 本科 | P32: 1999/09/01 | Q32: 26 | AM32: PMP | AN32: 2828477 | AP32: 是 | AQ32: =COUNTA(T32:AN32) -> 4
A33: 32 | B33: 常宁 | C33: 男 | D33: AAAAAABBBBBB | E33: 139xxxxxxx | F33: =VLOOKUP(B33,所有人!A:Q,16,FALSE) -> 411381198911227133 | G33: =VLOOKUP(B33,所有人!A:Q,9,FALSE) -> 武汉市 | I33: =VLOOKUP(B33,所有人!A:O,12,FALSE) -> 黄河科技学院 | J33: =VLOOKUP(B33,所有人!A:O,14,FALSE) -> 计算机科学与技术 | K33: =VLOOKUP(B33,所有人!A:Q,17,FALSE) -> 2015/04/13 | L33: =DATEDIF(K33,TODAY(),"Y") -> 11 | M33: =VLOOKUP(B33,所有人!A:Q,7,FALSE) -> 组长 | N33: 项目实施人员 | O33: 本科 | P33: 2012/09/15 | Q33: 13 | AM33: PMP | AN33: 3293034 | AP33: 是 | AQ33: =COUNTA(T33:AN33) -> 4
A34: 33 | B34: 钱奇 | C34: 男 | D34: AAAAAABBBBBB | E34: 139xxxxxxx | F34: =VLOOKUP(B34,所有人!A:Q,16,FALSE) -> 342601199110114675 | G34: =VLOOKUP(B34,所有人!A:Q,9,FALSE) -> 北京市 | I34: =VLOOKUP(B34,所有人!A:O,12,FALSE) -> 辽宁大学 | J34: =VLOOKUP(B34,所有人!A:O,14,FALSE) -> 计算机科学与技术 | K34: =VLOOKUP(B34,所有人!A:Q,17,FALSE) -> 2017/07/05 | L34: =DATEDIF(K34,TODAY(),"Y") -> 8 | M34: =VLOOKUP(B34,所有人!A:Q,7,FALSE) -> Java工程师 | N34: 项目经理 | O34: 本科 | P34: 2018/07/01 | Q34: 7 | AM34: PMP | AN34: 2253769 | AP34: 是 | AQ34: =COUNTA(T34:AN34) -> 4
A35: 34 | B35: 董晓晖 | C35: 男 | D35: AAAAAABBBBBB | E35: 139xxxxxxx | F35: =VLOOKUP(B35,所有人!A:Q,16,FALSE) -> 37068219891221021X | G35: =VLOOKUP(B35,所有人!A:Q,9,FALSE) -> 济南市 | I35: =VLOOKUP(B35,所有人!A:O,12,FALSE) -> 南京邮电大学通达学院 | J35: =VLOOKUP(B35,所有人!A:O,14,FALSE) -> 计算机科学与技术 | K35: =VLOOKUP(B35,所有人!A:Q,17,FALSE) -> 2016/08/22 | L35: =DATEDIF(K35,TODAY(),"Y") -> 9 | M35: =VLOOKUP(B35,所有人!A:Q,7,FALSE) -> 实施运维工程师 | N35: 测试人员 | O35: 本科 | P35: 2013/07/16 | Q35: 12 | AM35: PMP | AN35: 1893703 | AP35: 是 | AQ35: =COUNTA(T35:AN35) -> 4
A36: 35 | B36: 李宁 | C36: 男 | D36: AAAAAABBBBBB | E36: 139xxxxxxx | F36: =VLOOKUP(B36,所有人!A:Q,16,FALSE) -> 420901199107071111 | G36: =VLOOKUP(B36,所有人!A:Q,9,FALSE) -> 重庆市 | I36: =VLOOKUP(B36,所有人!A:O,12,FALSE) -> 三峡大学 | J36: =VLOOKUP(B36,所有人!A:O,14,FALSE) -> 工程管理 | K36: =VLOOKUP(B36,所有人!A:Q,17,FALSE) -> 2021/06/15 | L36: =DATEDIF(K36,TODAY(),"Y") -> 5 | M36: =VLOOKUP(B36,所有人!A:Q,7,FALSE) -> 区域首席客户经理 | N36: 项目实施人员 | O36: 本科 | P36: 2014/10/02 | Q36: 11 | Z36: CNITSEC2022CISE05642 | AP36: 是 | AQ36: =COUNTA(T36:AN36) -> 3
A37: 36 | B37: 许延一 | C37: 男 | D37: AAAAAABBBBBB | E37: 139xxxxxxx | F37: =VLOOKUP(B37,所有人!A:Q,16,FALSE) -> 130533199303076411 | G37: =VLOOKUP(B37,所有人!A:Q,9,FALSE) -> 北京市 | I37: =VLOOKUP(B37,所有人!A:O,12,FALSE) -> 河北科技师范学院 | J37: =VLOOKUP(B37,所有人!A:O,14,FALSE) -> 网络工程 | K37: =VLOOKUP(B37,所有人!A:Q,17,FALSE) -> 2016/08/16 | L37: =DATEDIF(K37,TODAY(),"Y") -> 9 | M37: =VLOOKUP(B37,所有人!A:Q,7,FALSE) -> 信息化产品经理 | N37: 项目实施人员 | O37: 本科 | P37: 2016/08/01 | Q37: 9 | Z37: CNITSEC2019CISE04351 | AP37: 是 | AQ37: =COUNTA(T37:AN37) -> 3
A38: 37 | B38: 马栋 | C38: 男 | D38: AAAAAABBBBBB | E38: 139xxxxxxx | F38: =VLOOKUP(B38,所有人!A:Q,16,FALSE) -> 410328198907209538 | G38: =VLOOKUP(B38,所有人!A:Q,9,FALSE) -> 北京市 | I38: =VLOOKUP(B38,所有人!A:O,12,FALSE) -> 北京邮电大学 | J38: =VLOOKUP(B38,所有人!A:O,14,FALSE) -> 计算机与科学 | K38: =VLOOKUP(B38,所有人!A:Q,17,FALSE) -> 2020/07/22 | L38: =DATEDIF(K38,TODAY(),"Y") -> 5 | M38: =VLOOKUP(B38,所有人!A:Q,7,FALSE) -> 解决方案经理 | N38: 项目实施人员 | O38: 本科 | P38: 2012/04/19 | Q38: 14 | Z38: CNITSEC2022CISE13830 | AM38: PMP | AN38: 3668357 | AP38: 是 | AQ38: =COUNTA(T38:AN38) -> 4
A39: 38 | B39: 冯亚南 | C39: 男 | D39: AAAAAABBBBBB | E39: 139xxxxxxx | F39: =VLOOKUP(B39,所有人!A:Q,16,FALSE) -> 37292219890606609X | G39: =VLOOKUP(B39,所有人!A:Q,9,FALSE) -> 郑州市 | I39: =VLOOKUP(B39,所有人!A:O,12,FALSE) -> 中国管理软件学院 | J39: =VLOOKUP(B39,所有人!A:O,14,FALSE) -> 计算机控制及应用 | K39: =VLOOKUP(B39,所有人!A:Q,17,FALSE) -> 2012/01/05 | L39: =DATEDIF(K39,TODAY(),"Y") -> 14 | M39: =VLOOKUP(B39,所有人!A:Q,7,FALSE) -> 项目经理 | N39: 项目经理 | O39: 本科 | P39: 2010/10/14 | Q39: 15 | Z39: CNITSEC2019CISE04360 | AA39: 2021CSAWOM0242(R) | AM39: PMP | AN39: 1859399 | AP39: 是 | AQ39: =COUNTA(T39:AN39) -> 4
A40: 39 | B40: 马洪彬 | C40: 男 | D40: AAAAAABBBBBB | E40: 139xxxxxxx | F40: =VLOOKUP(B40,所有人!A:Q,16,FALSE) -> 222323197601110017 | G40: =VLOOKUP(B40,所有人!A:Q,9,FALSE) -> 大连市 | I40: =VLOOKUP(B40,所有人!A:O,12,FALSE) -> 兰州大学 | J40: =VLOOKUP(B40,所有人!A:O,14,FALSE) -> 科技信息专业 | K40: =VLOOKUP(B40,所有人!A:Q,17,FALSE) -> 2017/09/11 | L40: =DATEDIF(K40,TODAY(),"Y") -> 8 | M40: =VLOOKUP(B40,所有人!A:Q,7,FALSE) -> 组长 | N40: 项目实施人员 | O40: 本科 | P40: 2001/07/11 | Q40: 24 | Z40: CNITSEC2019CISE04336 | AP40: 是 | AQ40: =COUNTA(T40:AN40) -> 3
...

Sheet 所有人
A1: 姓名 | B1: 最高学历 | C1: 出生日期 | D1: 首次参加工作时间 | E1: 一级部门名称 | F1: 二级部门名称 | G1: 岗位名称 | H1: 工作地点所在省 | I1: 工作地点所在市 | J1: 社保公积金缴纳地 | K1: 所属公司 | L1: 学校 | M1: 毕业时间 | N1: 专业 | O1: 学位 | P1: 身份证号 | Q1: 入职时间
A2: 阿曼太 | B2: 本科 | C2: 1982/11/26 | D2: 2006/09/01 | E2: 云网数据科学中心 | F2: 云网数据科学中心办公室1 | G2: 副总裁兼中心总经理 | H2: 北京市 | I2: 北京市 | J2: 北京 | K2: 北京恒安嘉新数智科技有限公司 | L2: 中央民族大学 | M2: 2006/07/01 | N2: 计算机科学与技术 | O2: 学士 | P2: 652328198211260016 | Q2: 2011/05/16
A3: 艾庆崴 | B3: 本科 | C3: 1986/08/26 | D3: 2011/02/21 | E3: 云网数据科学中心 | F3: 可信数据空间研发部 | G3: 组长 | H3: 湖北省 | I3: 武汉市 | J3: 武汉 | K3: 恒安嘉新（北京）科技股份公司 | L3: 中南财经政法大学 | M3: 2009/12/30 | N3: 金融保险 | O3: 学士 | P3: 422202198608261816 | Q3: 2021/07/01
A4: 安京玲 | B4: 本科 | C4: 1992/03/08 | D4: 2015/07/01 | E4: 证券部 | G4: 法务经理 | H4: 北京市 | I4: 北京市 | J4: 北京 | K4: 恒安嘉新（北京）科技股份公司 | L4: 河北科技师范学院 | M4: 2015/06/19 | N4: 法学 | O4: 学士 | P4: 132201199203086043 | Q4: 2017/07/26
A5: 敖仕1 | B5: 本科 | C5: 1994/04/21 | D5: 2013/10/16 | E5: 云网数据科学中心 | F5: 基础网络算力工程部 | G5: 实施运维工程师 | H5: 贵州省 | I5: 贵阳市 | J5: 北京 | K5: 恒安嘉新（北京）科技股份公司 | L5: 北京外国语大学 | M5: 2022/09/23 | N5: 信息管理与信息技术 | O5: 无 | P5: 522121199404215238 | Q5: 2025/07/07
A6: 白首骏 | B6: 本科 | C6: 1990/10/30 | D6: 2013/06/24 | E6: 云网数据科学中心 | F6: 金川-IDC/DNS智能体产品研发部 | G6: Java工程师 | H6: 北京市 | I6: 北京市 | J6: 北京 | K6: 恒安嘉新（北京）科技股份公司 | L6: 北京城市学院 | M6: 2013/06/08 | N6: 计算机科学与技术 | O6: 学士 | P6: 110101199010304031 | Q6: 2020/03/25
A7: 白喆 | B7: 本科 | C7: 1979/07/16 | D7: 2002/06/01 | E7: 市场连锁经营中心 | F7: 陕西-销售 | G7: 客户总监 | H7: 陕西省 | I7: 西安市 | J7: 西安 | K7: 恒安嘉新（北京）科技股份公司 | L7: 西安电子科技大学 | M7: 2002/06/01 | N7: 计算机应用 | O7: 学士 | P7: 612725197907163012 | Q7: 2017/02/06
A8: 班宏 | B8: 本科 | C8: 1998/10/31 | D8: 2020/08/01 | E8: 云网数据科学中心 | F8: 合成作战数据智能运营部 | G8: 系统运营经理 | H8: 广西壮族自治区 | I8: 南宁市 | J8: 南宁 | K8: 恒安嘉新（北京）科技股份公司 | L8: 广西民族师范学院 | M8: 2021/06/20 | N8: 网络工程 | O8: 学士 | P8: 452727199810310014 | Q8: 2021/05/14
A9: 鲍永昌 | B9: 本科 | C9: 1987/05/03 | D9: 2010/01/18 | E9: 云网数据科学中心 | F9: 咨询交付服务增长部 | G9: 解决方案经理 | H9: 河北省 | I9: 石家庄市 | J9: 石家庄 | K9: 恒安嘉新（北京）科技股份公司 | L9: 北京邮电大学 | M9: 2013/01/31 | N9: 通信工程 | O9: 学士 | P9: 130182198705036675 | Q9: 2018/10/08
A10: 鲍雨 | B10: 本科 | C10: 1995/08/11 | D10: 2015/06/01 | E10: 云网数据科学中心 | F10: 合成作战数据智能运营部 | G10: 系统运营专家 | H10: 江西省 | I10: 南昌市 | J10: 南昌 | K10: 恒安嘉新（北京）科技股份公司 | L10: 华南理工大学网络教育学院 | M10: 2020/01/30 | N10: 计算机科学与技术 | O10: 学士 | P10: 362201199508112831 | Q10: 2022/01/04
A11: 边桂锋 | B11: 大专及其以下 | C11: 1981/06/05 | D11: 1998/01/01 | E11: 人教行政服务中心 | F11: 行政管理部 | G11: 行政专员 | H11: 北京市 | I11: 北京市 | J11: 北京 | K11: 北京恒安嘉新数智科技有限公司 | L11: 无 | M11: 2013/01/01 | N11: 无 | O11: 无 | P11: 410781198106054154 | Q11: 2020/11/06
A12: 卜凡成1 | B12: 本科 | C12: 1994/02/01 | D12: 2016/07/01 | E12: 云网数据科学中心 | F12: 金御-工业互联网智能体产品研发部 | G12: Java工程师 | H12: 山东省 | I12: 济南市 | J12: 济南 | K12: 恒安嘉新（北京）科技股份公司 | L12: 山东理工大学 | M12: 2016/07/01 | N12: 电子信息科学与技术 | O12: 学士 | P12: 371102199402017512 | Q12: 2021/06/01
A13: 步学剑 | B13: 本科 | C13: 1992/08/24 | D13: 2015/10/10 | E13: 云网数据科学中心 | F13: 金御-网综智能体产品研发部 | G13: Java工程师 | H13: 天津市 | I13: 天津市 | J13: 天津 | K13: 恒安嘉新（北京）科技股份公司 | L13: 湖南农业大学 | M13: 2015/06/30 | N13: 食品科学与工程 | O13: 学士 | P13: 120222199208243616 | Q13: 2023/04/12
A14: 蔡骏潇 | B14: 本科 | C14: 1990/08/05 | D14: 2013/08/08 | E14: 云网数据科学中心 | F14: 咨询交付服务增长部 | G14: 解决方案经理 | H14: 宁夏回族自治区 | I14: 银川市 | J14: 银川 | K14: 恒安嘉新（北京）科技股份公司 | L14: 西安邮电大学 | M14: 2017/12/22 | N14: 电子与通信工程 | O14: 硕士 | P14: 640102199008051514 | Q14: 2021/06/16
A15: 蔡小龙 | B15: 本科 | C15: 1989/08/30 | D15: 2011/07/12 | E15: 云网数据科学中心 | F15: 合成作战数据智能运营部 | G15: 跨专业支持工程师 | H15: 宁夏回族自治区 | I15: 银川市 | J15: 银川 | K15: 恒安嘉新（北京）科技股份公司 | L15: 北京邮电大学 | M15: 2011/06/23 | N15: 电子信息工程 | O15: 学士 | P15: 640302198908300711 | Q15: 2023/02/06
A16: 蔡晓勇 | B16: 本科 | C16: 1991/06/11 | D16: 2014/08/01 | E16: 云网数据科学中心 | F16: 合成作战数据智能运营部 | G16: 系统运营经理 | H16: 福建省 | I16: 福州市 | J16: 福州 | K16: 恒安嘉新（北京）科技股份公司 | L16: 福建工程学院 | M16: 2014/06/20 | N16: 电子信息工程 | O16: 学士 | P16: 350302199106113119 | Q16: 2026/04/01
... A54: 陈炜 | B54: 大专及其以下 | C54: 1978/05/18 | D54: 1996/09/16 | E54: 市场连锁经营中心 | F54: 福建-销售 | G54: 客户总监 | H54: 福建省 | I54: 福州市 | J54: 福州 | K54: 恒安嘉新（北京）科技股份公司 | L54: 湖南大学 | M54: 2003/12/01 | N54: 法学 | O54: 无 | P54: 352201197805180039 | Q54: 2020/12/04
A55: 陈晓光 | B55: 硕士研究生 | C55: 1982/10/24 | D55: 2008/07/01 | E55: CEO办 | G55: CEO | H55: 北京市 | I55: 北京市 | J55: 北京 | K55: 北京恒安嘉新数智科技有限公司 | L55: 北京邮电大学 | M55: 2008/04/20 | N55: 信息安全 | O55: 硕士 | P55: 130103198210241276 | Q55: 2010/10/01
A56: 陈晓鹏 | B56: 本科 | C56: 1973/07/13 | D56: 1997/09/01 | E56: 云网数据科学中心 | F56: Dev&LLMOps研发 | G56: Go语言工程师 | H56: 北京市 | I56: 北京市 | J56: 北京 | K56: 恒安嘉新（北京）科技股份公司 | L56: 清华大学 | M56: 1997/07/01 | N56: 电子工程 | O56: 学士 | P56: 110105197307130817 | Q56: 2021/06/02
A57: 陈雅琴 | B57: 硕士研究生 | C57: 1977/10/17 | D57: 2000/07/01 | E57: 保密管理办公室 | G57: 保密总监 | H57: 北京市 | I57: 北京市 | J57: 北京 | K57: 恒安嘉新（北京）科技股份公司 | L57: 北京师范大学 | M57: 2024/06/30 | N57: 工商管理 | O57: 硕士 | P57: 421002197710170025 | Q57: 2020/07/09
A58: 陈扬 | B58: 本科 | C58: 1991/01/30 | D58: 2012/08/15 | E58: 云网数据科学中心 | F58: 咨询交付专家部 | G58: 解决方案专家 | H58: 陕西省 | I58: 西安市 | J58: 西安 | K58: 恒安嘉新（北京）科技股份公司 | L58: 西安邮电大学 | M58: 2012/07/05 | N58: 光电信息工程 | O58: 学士 | P58: 610528199101300036 | Q58: 2019/05/27
A59: 陈杨1 | B59: 本科 | C59: 1993/08/08 | D59: 2016/06/01 | E59: 云网数据科学中心 | F59: 数智产品架构部 | G59: 产品设计专家 | H59: 湖北省 | I59: 武汉市 | J59: 武汉 | K59: 恒安嘉新（北京）科技股份公司 | L59: 湖北汽车工业学院 | M59: 2016/06/01 | N59: 工业设计 | O59: 学士 | P59: 421121199308082020 | Q59: 2021/06/01
A60: 陈永坤 | B60: 本科 | C60: 1996/11/13 | D60: 2018/07/01 | E60: 云网数据科学中心 | F60: 网络安全模型研发部 | G60: 安全分析工程师 | H60: 山东省 | I60: 济南市 | J60: 济南 | K60: 恒安嘉新（北京）科技股份公司 | L60: 江西理工大学 | M60: 2019/06/01 | N60: 信息安全 | O60: 学士 | P60: 412727199611134030 | Q60: 2020/12/14
A61: 陈宇 | B61: 硕士研究生 | C61: 1975/05/05 | D61: 1998/09/01 | E61: 云网数据科学中心 | F61: 咨询交付服务增长部 | G61: 解决方案经理 | H61: 内蒙古自治区 | I61: 呼和浩特市 | J61: 北京 | K61: 恒安嘉新（北京）科技股份公司 | L61: 内蒙古大学 | M61: 2009/04/01 | N61: 工商管理 | O61: 硕士 | P61: 150103197505051030 | Q61: 2020/09/14
A62: 陈宇鹏1 | B62: 本科 | C62: 1999/11/05 | D62: 2021/12/01 | E62: 云网数据科学中心 | F62: 基础网络算力工程部 | G62: 实施运维工程师 | H62: 福建省 | I62: 厦门市 | J62: 福州 | K62: 恒安嘉新（北京）科技股份公司 | L62: 西安电子科技大学 | M62: 2021/06/23 | N62: 信息安全 | O62: 学士 | P62: 35058319991105603X | Q62: 2022/08/01
A63: 陈曾 | B63: 大专及其以下 | C63: 1997/01/18 | D63: 2016/07/14 | E63: 云网数据科学中心 | F63: 合成作战数据智能运营部 | G63: 系统运营经理 | H63: 上海市 | I63: 上海市 | J63: 上海 | K63: 恒安嘉新（上海）科技有限公司 | L63: 武汉警官职业学院 | M63: 2017/06/15 | N63: 计算机网络技术 | O63: 无 | P63: 420117199701180019 | Q63: 2022/03/22
A64: 陈钊2 | B64: 本科 | C64: 1993/06/03 | D64: 2017/03/20 | E64: 云网数据科学中心 | F64: 金御-工业互联网智能体产品研发部 | G64: Java工程师 | H64: 山东省 | I64: 济南市 | J64: 济南 | K64: 恒安嘉新（北京）科技股份公司 | L64: 山东工商学院 | M64: 2017/06/01 | N64: 计算机科学与技术 | O64: 学士 | P64: 372328199306030333 | Q64: 2021/07/05
A65: 陈振 | B65: 本科 | C65: 1985/07/19 | D65: 2009/09/21 | E65: 云网数据科学中心 | F65: 通信网安全模型研发部 | G65: 大数据工程师 | H65: 广东省 | I65: 广州市 | J65: 广州 | K65: 恒安嘉新（北京）科技股份公司 | L65: 河南理工大学 | M65: 2009/07/03 | N65: 计算机科学与技术 | O65: 学士 | P65: 411481198507199017 | Q65: 2018/07/24
A66: 成春鸽 | B66: 本科 | C66: 1981/03/18 | D66: 2003/03/24 | E66: 云网数据科学中心 | F66: 基础网络算力工程部 | G66: 实施运维工程师 | H66: 上海市 | I66: 上海市 | J66: 上海 | K66: 恒安嘉新（上海）科技有限公司 | L66: 复旦大学 | M66: 2011/06/30 | N66: 计算机网络 | O66: 无 | P66: 430422198103181219 | Q66: 2023/02/27
A67: 程利明 | B67: 大专及其以下 | C67: 1984/10/22 | D67: 2008/05/01 | E67: 云网数据科学中心 | F67: 合成作战数据智能运营部 | G67: 系统运营经理 | H67: 湖北省 | I67: 武汉市 | J67: 北京 | K67: 恒安嘉新（北京）科技股份公司 | L67: 河北金融学院 | M67: 2008/05/01 | N67: 计算机 | O67: 无 | P67: 422326198410225517 | Q67: 2012/07/02
A68: 仇红建1 | B68: 本科 | C68: 1988/01/05 | D68: 2010/06/23 | E68: 云网数据科学中心 | F68: 合成作战数据智能运营部 | G68: 跨专业支持工程师 | H68: 天津市 | I68: 天津市 | J68: 天津 | K68: 恒安嘉新（北京）科技股份公司 | L68: 天津理工大学 | M68: 2010/06/21 | N68: 光信息科学与技术 | O68: 学士 | P68: 120225198801053316 | Q68: 2022/07/28
A69: 从继通 | B69: 本科 | C69: 1985/10/15 | D69: 2008/07/07 | E69: 云网数据科学中心 | F69: 金御-网综智能体产品研发部 | G69: Java工程师 | H69: 天津市 | I69: 天津市 | J69: 天津 | K69: 恒安嘉新（北京）科技股份公司 | L69: 大连民族学院 | M69: 2008/06/30 | N69: 软件工程 | O69: 学士 | P69: 12010119851015353X | Q69: 2019/05/08
... A106: 范晓波 | B106: 本科 | C106: 1992/03/04 | D106: 2016/02/14 | E106: 云网数据科学中心 | F106: 云河-零信任企业安全产品研发部 | G106: Go语言工程师 | H106: 北京市 | I106: 北京市 | J106: 北京 | K106: 恒安嘉新（北京）科技股份公司 | L106: 太原工业学院 | M106: 2016/07/01 | N106: 自动化 | O106: 学士 | P106: 142325199203045514 | Q106: 2020/11/09
A107: 范旭 | B107: 大专及其以下 | C107: 1987/09/23 | D107: 2010/10/08 | E107: 用户体验研发中心 | G107: UI设计师 | H107: 河北省 | I107: 雄安 | J107: 雄安 | K107: 恒安嘉新（雄安）数智科技有限公司 | L107: 秦皇岛职业技术学院 | M107: 2010/01/01 | N107: 视觉传达 | O107: 无 | P107: 130181198709237929 | Q107: 2015/09/23
A108: 范志华 | B108: 大专及其以下 | C108: 1981/09/04 | D108: 2003/12/01 | E108: 云网数据科学中心 | F108: 合成作战数据智能运营部 | G108: 系统运营经理 | H108: 山东省 | I108: 济南市 | J108: 济南 | K108: 恒安嘉新（北京）科技股份公司 | L108: 江西财经理工学院 | M108: 2003/07/01 | N108: 计算机 | O108: 无 | P108: 412721198109041434 | Q108: 2015/12/28
A109: 方心蕊 | B109: 本科 | C109: 1994/06/03 | D109: 2015/05/01 | E109: 市场连锁经营中心 | F109: 增值连锁经营管理部 | G109: 市场副总监 | H109: 北京市 | I109: 北京市 | J109: 北京 | K109: 北京恒安嘉新数智科技有限公司 | L109: 华北科技学院 | M109: 2015/07/01 | N109: 新闻学 | O109: 学士 | P109: 15210419940603032X | Q109: 2019/04/04
A110: 方渝鑫 | B110: 本科 | C110: 1994/05/08 | D110: 2017/04/01 | E110: 云网数据科学中心 | F110: 合成作战数据智能运营部 | G110: 系统运营经理 | H110: 西藏自治区 | I110: 拉萨市 | J110: 拉萨 | K110: 恒安嘉新（北京）科技股份公司 | L110: 重庆大学 | M110: 2024/07/01 | N110: 计算机科学与技术 | O110: 学士 | P110: 500102199405088459 | Q110: 2025/04/08
A111: 方宇 | B111: 硕士研究生 | C111: 1987/05/21 | D111: 2013/08/01 | E111: 财经管理服务中心 | F111: 财经管理服务中心办公室 | G111: 财务副总监 | H111: 北京市 | I111: 北京市 | J111: 北京 | K111: 恒安嘉新（北京）科技股份公司 | L111: 北京工商大学 | M111: 2013/06/30 | N111: 财务管理 | O111: 硕士 | P111: 152102198705212716 | Q111: 2026/04/01
A112: 方子玉 | B112: 硕士研究生 | C112: 1997/04/23 | D112: 2025/06/15 | E112: 云网数据科学中心 | F112: 金川-IDC/DNS智能体产品研发部 | G112: AI算法工程师 | H112: 湖北省 | I112: 武汉市 | J112: 武汉 | K112: 国嘉网信（武汉）安全技术有限公司 | L112: 华南师范大学 | M112: 2025/06/01 | N112: 计算机科学与技术 | O112: 硕士 | P112: 420104199704231617 | Q112: 2026/03/24
A113: 冯杰 | B113: 本科 | C113: 1989/05/15 | D113: 2014/06/10 | E113: 云网数据科学中心 | F113: 合成作战数据智能运营部 | G113: 系统运营经理 | H113: 河南省 | I113: 郑州市 | J113: 郑州 | K113: 恒安嘉新（北京）科技股份公司 | L113: 河南工业大学 | M113: 2014/12/30 | N113: 模具设计与制造 | O113: 学士 | P113: 41272619890515639X | Q113: 2022/10/17
...

Sheet Projects
A1: Name | B1: Summary | C1: Year | D1: Begin | E1: End | F1: Scope | G1: Begin1 | H1: End1
A2: 2022上海移动技术中台 | B2: 2022上海移动技术中台 | C2: 2022 | D2: 2022.2 | E2: 2023.4 | F2: AAAA | G2: =C2&"."&RANDBETWEEN(1,8) -> 2022.8 | H2: =(C2+1)&"."&RANDBETWEEN(1,12) -> 2023.1
A3: 2023年四川分中心数据中台项目 | B3: 根据工作和业务需要，建设大数据平台，主要内容包括：一套具备数据汇聚、存储、应用、共享的清江大数据平台，包括一个网络信息安全综合数据中心、两个网络信息安全综合业务系统(网络分析系统改造、网络综合管理系统)。 | C3: 2023 | D3: 2023.1 | E3: 2024.11 | F3: AAAA | G3: =C3&"."&RANDBETWEEN(1,8) -> 2023.5 | H3: =(C3+1)&"."&RANDBETWEEN(1,12) -> 2024.4
A4: 2023年山东移动工业互联网安全态势感知互联网专线扩容项目 | B4: 2023年山东移动工业互联网安全态势感知互联网专线扩容项目 | C4: 2023 | D4: 2023.7 | E4: 2024.3 | F4: AAAA | G4: =C4&"."&RANDBETWEEN(1,8) -> 2023.1 | H4: =(C4+1)&"."&RANDBETWEEN(1,12) -> 2024.9
A5: 2023-2024年中国联通软研院数据中台数据能力数据仓库研发项目（溯源数据模型研发） | B5: 中国联通软研院数据中台数据能力数据仓库研发项目（溯源数据模型研发） | C5: 2023 | D5: 2023.2 | E5: 2024.9 | F5: AAAA | G5: =C5&"."&RANDBETWEEN(1,8) -> 2023.3 | H5: =(C5+1)&"."&RANDBETWEEN(1,12) -> 2024.7
A6: 2022江苏管局车联网安全态势感知平台 | B6: 2022江苏管局车联网安全态势感知平台 | C6: 2022 | D6: 2022.7 | E6: 2023.9 | F6: AAAA | G6: =C6&"."&RANDBETWEEN(1,8) -> 2022.6 | H6: =(C6+1)&"."&RANDBETWEEN(1,12) -> 2023.4
A7: 2022年中国电信态势感知项目 | B7: 2022年中国电信态势感知项目 | C7: 2022 | D7: 2022.7 | E7: 2023.9 | F7: AAAA | G7: =C7&"."&RANDBETWEEN(1,8) -> 2022.7 | H7: =(C7+1)&"."&RANDBETWEEN(1,12) -> 2023.2
A8: 2023年中国联通内蒙古应用安全态势感知平台研发采购项目 | B8: 2023年中国联通内蒙古应用安全态势感知平台研发采购项目 | C8: 2023 | D8: 2023.1 | E8: 2024.10 | F8: AAAA | G8: =C8&"."&RANDBETWEEN(1,8) -> 2023.6 | H8: =(C8+1)&"."&RANDBETWEEN(1,12) -> 2024.2
A9: 2023年江苏分中心无锡网信办态势感知平台四期 | B9: 2023年江苏分中心无锡网信办态势感知平台四期 | C9: 2022 | D9: 2022.1 | E9: 2023.12 | F9: AAAA | G9: =C9&"."&RANDBETWEEN(1,8) -> 2022.1 | H9: =(C9+1)&"."&RANDBETWEEN(1,12) -> 2023.2
A10: 022年中国联通软研院数据中台数据能力溯源数据采集研发项目（网络数据营销场景赋能）委托开发框架协议 | B10: 2022年中国联通软研院数据中台数据能力溯源数据采集研发项目（网络数据营销场景赋能） | C10: 2023 | D10: 2023.3 | E10: 2024.6 | F10: AAAA | G10: =C10&"."&RANDBETWEEN(1,8) -> 2023.3 | H10: =(C10+1)&"."&RANDBETWEEN(1,12) -> 2024.5
A11: 中国电信北京公司2022年5G SA移动恶意程序物联网基础安全接入和威胁监测管理升级项目-软件开发合同 | B11: 2022年北京电信物联网平台项目 | C11: 2022 | D11: 2022.5 | E11: 2023.1 | F11: AAAA | G11: =C11&"."&RANDBETWEEN(1,8) -> 2022.3 | H11: =(C11+1)&"."&RANDBETWEEN(1,12) -> 2023.10
A12: 中国移动江苏公司手机恶意软件监控系统八期工程应用软件开发采购合同 | B12: 2023年江苏移动手机恶意软件监测系统八期扩容 | C12: 2023 | D12: 2023.4 | E12: 2024.2 | F12: AAAA | G12: =C12&"."&RANDBETWEEN(1,8) -> 2023.6 | H12: =(C12+1)&"."&RANDBETWEEN(1,12) -> 2024.9
A13: 手机恶意软件监控系统开发十一期工程（CM平台）应用软件开发与系统集成服务合同 | B13: 2023年移动集团手机恶意软件监控系统十一期工程应用软件开发与系统集成服务项目（CM平台） | C13: 2023 | D13: 2023.4 | E13: 2024.4 | F13: AAAA | G13: =C13&"."&RANDBETWEEN(1,8) -> 2023.2 | H13: =(C13+1)&"."&RANDBETWEEN(1,12) -> 2024.11
... A105: 2025年部委/集团总部中国移动僵木蠕集中管理平台五期工程 | B105: 中国移动2025年至2026年僵木蠕集中管理平台五期工程采购服务合同 | C105: 2026 | D105: 2026.6 | E105: 2027.1 | F105: AAAA | G105: =C105&"."&RANDBETWEEN(1,8) -> 2026.7 | H105: =(C105+1)&"."&RANDBETWEEN(1,12) -> 2027.5
A106: 2025年河北移动恶意程序平台扩容 | B106: 移动网流量安全监测处置系统四期-安全 监测管理平台研发项目合同 | C106: 2026 | D106: 2026.8 | E106: 2027.9 | G106: =C106&"."&RANDBETWEEN(1,8) -> 2026.6 | H106: =(C106+1)&"."&RANDBETWEEN(1,12) -> 2027.10

Sheet Duty
A1: Duty | B1: Desc
A2: 项目经理 | B2: 负责项目整体统筹规划，制定项目计划与里程碑；协调甲方与项目团队资源；把控项目进度、成本与质量，解决项目中的跨部门沟通问题，确保项目按期交付。
A3: 解决方案经理 | B3: 对接甲方需求，完成系统的解决方案设计与标书编制；参与需求评审，向研发团队传递甲方核心需求；配合项目实施进行方案落地指导，完成用户培训与需求迭代。
A4: 解决方案总监 | B4: 统筹全国各区域项目解决方案的整体设计；负责高难度需求的方案攻坚，把控方案的可行性与创新性；对接甲方高层，推动解决方案的落地与合作签约。
A5: 研发经理 | B5: 负责研发团队的人员管理与任务分配；制定系统的技术架构与研发规范；参与核心模块的技术攻坚，把控研发进度与代码质量，解决研发过程中的技术问题。
A6: 大数据工程师 | B6: 负责项目的大数据建模与数据清洗；基于用户行为数据构建涉诈识别特征工程；实现大数据平台的数仓搭建与ETL任务开发，支撑反诈系统的数据分析需求。
A7: 算法工程师 | B7: 研发行为识别算法（如机器学习/深度学习模型）；优化算法模型的准确率与实时性；对接研发团队完成算法模型的工程化部署，持续迭代优化模型效果。
A8: 软件开发 | B8: 参与系统的模块开发与代码编写；根据需求文档完成功能实现与单元测试；配合测试人员修复bug，参与系统联调与上线部署，完成技术文档编写。
A9: 测试人员 | B9: 制定系统的测试计划与测试用例；执行功能测试、性能测试、兼容性测试；记录并跟踪bug，与研发团队协同修复；完成测试报告编制，确保系统上线质量。
A10: 质控工程师 | B10: 建立项目质量管控体系，制定质控标准与流程；对项目各阶段（需求/研发/实施）进行质量检查；识别质量风险并提出整改方案，推动项目整体质量提升。
A11: 运维人员 | B11: 负责系统的日常运维与监控，保障系统7*24小时稳定运行；处理系统故障与性能问题，进行系统扩容与优化；完成系统备份与灾备演练，制定运维应急预案。
A12: 项目实施人员 | B12: 负责项目现场落地、需求对接与方案执行，协调客户、研发及测试资源，完成部署、调试与培训，保障项目按期交付，处理实施问题并提供售后支持。
... A15: 软件开发人员 | B15: 根据需求与架构进行代码开发、单元测试，修复缺陷，参与技术评审与联调，遵循开发规范，保障功能实现、代码质量与项目进度。
